[2025-01-16 16:03:44,664][modelflow.modelflow.__main__][DEBUG] - DEBUG ENABLED
[2025-01-16 16:03:44,664][modelflow.__main__][INFO] - Launch command: ['/home/kuhmichel/anaconda3/envs/eki/bin/modelflow', 'debug=True', 'run=manuelsequence']
[2025-01-16 16:03:44,664][modelflow.__main__][INFO] - Storing run config in global...
[2025-01-16 16:03:44,664][modelflow.__main__][DEBUG] - config:
[2025-01-16 16:03:44,664][modelflow.__main__][DEBUG] - {'debug': True, 'run': {'_target_': 'modelflow.run.ManuelSequence', 'tasks': [{'_target_': 'modelflow.run.Sequence', 'common_cmd_args': 'run=train dataset=tsV2 dataset.dataloader.batch_size=2 tokenizer=hf tokenizer.encoding=fhswf/BPE_GPT2_TinyStoriesV2_cleaned_2048 run.epochs=1 tokenizer=hf_gptneo +model.type=CHECKPOINT  model=NEW_BENCH2 quantization=qat quantization/model=NEW_BENCH2b run.export=True', 'tasks': [{'cmd_args': '', '_target_': 'modelflow.command.QTransformCommand'}]}, {'_target_': 'modelflow.run.Sequence', 'common_cmd_args': '', 'tasks': [{'cmd_args': '', 'type': 'modelflow.command.QTransformCommand'}, {'cmd_args': '', 'type': 'modelflow.command.QTransformCommand'}, {'cmd_args': '', 'type': 'modelflow.command.QTransformCommand'}, {'type': 'modelflow.run.Paralell', 'common_cmd_args': '', 'tasks': [{'cmd_args': '', 'type': 'modelflow.command.QTransformCommand'}, {'cmd_args': '', 'type': 'modelflow.command.QTransformCommand'}, {'cmd_args': '', 'type': 'modelflow.command.QTransformCommand'}]}, {'cmd_args': '', 'type': 'modelflow.command.QTransformCommand'}, {'cmd_args': '', 'type': 'modelflow.command.QTransformCommand'}]}]}, 'runtime': {'choices': {'run': 'manuelsequence', 'hydra/env': 'default', 'hydra/callbacks': None, 'hydra/job_logging': 'perlevel', 'hydra/hydra_logging': 'default', 'hydra/hydra_help': 'default', 'hydra/help': 'main', 'hydra/sweeper': 'basic', 'hydra/launcher': 'basic', 'hydra/output': 'default'}}}
[2025-01-16 16:03:44,670][modelflow.__main__][CRITICAL] - Script execution failed. Reason: Error locating target 'modelflow.run.ManuelSequence', set env var HYDRA_FULL_ERROR=1 to see chained exception.
full_key: run
Traceback (most recent call last):
  File "/home/kuhmichel/anaconda3/envs/eki/lib/python3.10/site-packages/hydra/_internal/utils.py", line 650, in _locate
    obj = import_module(mod)
  File "/home/kuhmichel/anaconda3/envs/eki/lib/python3.10/importlib/__init__.py", line 126, in import_module
    return _bootstrap._gcd_import(name[level:], package, level)
  File "<frozen importlib._bootstrap>", line 1050, in _gcd_import
  File "<frozen importlib._bootstrap>", line 1027, in _find_and_load
  File "<frozen importlib._bootstrap>", line 1006, in _find_and_load_unlocked
  File "<frozen importlib._bootstrap>", line 688, in _load_unlocked
  File "<frozen importlib._bootstrap_external>", line 883, in exec_module
  File "<frozen importlib._bootstrap>", line 241, in _call_with_frames_removed
  File "/home/kuhmichel/git/eki-transformer-dev/modelflow/modelflow/run/__init__.py", line 1, in <module>
    from modelflow.run.manuelsequence import ManuelSequence
  File "/home/kuhmichel/git/eki-transformer-dev/modelflow/modelflow/run/manuelsequence.py", line 15, in <module>
    class ManuelSequence(TaskList):
  File "/home/kuhmichel/git/eki-transformer-dev/modelflow/modelflow/run/manuelsequence.py", line 16, in ManuelSequence
    scheduler: Scheduler = instantiate(CFG().scheduler)
  File "/home/kuhmichel/anaconda3/envs/eki/lib/python3.10/site-packages/omegaconf/dictconfig.py", line 359, in __getattr__
    self._format_and_raise(key=key, value=None, cause=e)
  File "/home/kuhmichel/anaconda3/envs/eki/lib/python3.10/site-packages/omegaconf/base.py", line 231, in _format_and_raise
    format_and_raise(
  File "/home/kuhmichel/anaconda3/envs/eki/lib/python3.10/site-packages/omegaconf/_utils.py", line 819, in format_and_raise
    _raise(ex, cause)
  File "/home/kuhmichel/anaconda3/envs/eki/lib/python3.10/site-packages/omegaconf/_utils.py", line 797, in _raise
    raise ex.with_traceback(sys.exc_info()[2])  # set env var OC_CAUSE=1 for full trace
  File "/home/kuhmichel/anaconda3/envs/eki/lib/python3.10/site-packages/omegaconf/dictconfig.py", line 351, in __getattr__
    return self._get_impl(
  File "/home/kuhmichel/anaconda3/envs/eki/lib/python3.10/site-packages/omegaconf/dictconfig.py", line 442, in _get_impl
    node = self._get_child(
  File "/home/kuhmichel/anaconda3/envs/eki/lib/python3.10/site-packages/omegaconf/basecontainer.py", line 73, in _get_child
    child = self._get_node(
  File "/home/kuhmichel/anaconda3/envs/eki/lib/python3.10/site-packages/omegaconf/dictconfig.py", line 475, in _get_node
    self._validate_get(key)
  File "/home/kuhmichel/anaconda3/envs/eki/lib/python3.10/site-packages/omegaconf/dictconfig.py", line 164, in _validate_get
    self._format_and_raise(
  File "/home/kuhmichel/anaconda3/envs/eki/lib/python3.10/site-packages/omegaconf/base.py", line 231, in _format_and_raise
    format_and_raise(
  File "/home/kuhmichel/anaconda3/envs/eki/lib/python3.10/site-packages/omegaconf/_utils.py", line 899, in format_and_raise
    _raise(ex, cause)
  File "/home/kuhmichel/anaconda3/envs/eki/lib/python3.10/site-packages/omegaconf/_utils.py", line 797, in _raise
    raise ex.with_traceback(sys.exc_info()[2])  # set env var OC_CAUSE=1 for full trace
  File "/home/kuhmichel/anaconda3/envs/eki/lib/python3.10/site-packages/hydra/_internal/utils.py", line 644, in _locate
    obj = getattr(obj, part)
omegaconf.errors.ConfigAttributeError: Key 'scheduler' is not in struct
    full_key: scheduler
    object_type=dict

The above exception was the direct cause of the following exception:

Traceback (most recent call last):
  File "/home/kuhmichel/anaconda3/envs/eki/lib/python3.10/site-packages/hydra/_internal/instantiate/_instantiate2.py", line 134, in _resolve_target
    target = _locate(target)
  File "/home/kuhmichel/anaconda3/envs/eki/lib/python3.10/site-packages/hydra/_internal/utils.py", line 658, in _locate
    raise ImportError(
ImportError: Error loading 'modelflow.run.ManuelSequence':
ConfigAttributeError("Key 'scheduler' is not in struct\n    full_key: scheduler\n    object_type=dict")

The above exception was the direct cause of the following exception:

Traceback (most recent call last):
  File "/home/kuhmichel/git/eki-transformer-dev/modelflow/modelflow/__main__.py", line 57, in main
    app = instantiate(cfg.run)
  File "/home/kuhmichel/anaconda3/envs/eki/lib/python3.10/site-packages/hydra/_internal/instantiate/_instantiate2.py", line 226, in instantiate
    return instantiate_node(
  File "/home/kuhmichel/anaconda3/envs/eki/lib/python3.10/site-packages/hydra/_internal/instantiate/_instantiate2.py", line 333, in instantiate_node
    _target_ = _resolve_target(node.get(_Keys.TARGET), full_key)
  File "/home/kuhmichel/anaconda3/envs/eki/lib/python3.10/site-packages/hydra/_internal/instantiate/_instantiate2.py", line 139, in _resolve_target
    raise InstantiationException(msg) from e
hydra.errors.InstantiationException: Error locating target 'modelflow.run.ManuelSequence', set env var HYDRA_FULL_ERROR=1 to see chained exception.
full_key: run
[2025-01-16 16:03:44,671][modelflow.__main__][ERROR] - Exited with Status Code: 1
